<?xml version="1.0" encoding="utf-8"?>
<robot name="xarm6">
  <link name="world"/>
  <joint name="world_joint" type="fixed">
    <parent link="world"/>
    <child link="link_base"/>
    <origin rpy="0 0 0" xyz="0 0 0"/>
  </joint>
  <link name="link_base">
    <collision>
      <geometry>
        <cylinder length="0.104" radius="0.06"/>
      </geometry>
      <origin rpy="0 0 0" xyz="0 0 0.097"/>
    </collision> 
  </link>
  <link name="link1">
    <collision>
      <geometry>
        <cylinder length="0" radius="0.09"/>
      </geometry>
      <origin rpy="0 0 0" xyz="0 0.034 -0.032"/>
    </collision>
  </link>
  <joint name="joint1" type="revolute">
    <parent link="link_base"/>
    <child link="link1"/>
    <origin rpy="0 0 0" xyz="0 0 0.267"/>
    <axis xyz="0 0 1"/>
    <limit effort="50.0" lower="-6.28318530718" upper="6.28318530718" velocity="3.14"/>
  </joint>
  <link name="link2">
    <collision>
      <geometry>
        <cylinder length="0.21" radius="0.095"/>
      </geometry>
      <origin rpy="-1.57079632679489661923 0  0 " xyz="0 -0.134 0.024 "/>
    </collision>
  </link>
  <joint name="joint2" type="revolute">
    <parent link="link1"/>
    <child link="link2"/>
    <origin rpy="-1.57079632679489661923 0 0" xyz="0 0 0"/>
    <axis xyz="0 0 1"/>
    <limit effort="50.0" lower="-2.059" upper="2.0944" velocity="3.14"/>
  </joint>
  <link name="link3">
    <collision>
      <geometry>
        <cylinder length="0.11" radius="0.095"/>
      </geometry>
      <origin rpy="0 -1.57079632679489661923 0.7" xyz="0.05 0.047 0.016 "/>
    </collision>
  </link>
  <joint name="joint3" type="revolute">
    <parent link="link2"/>
    <child link="link3"/>
    <origin rpy="0 0 0" xyz="0.0535 -0.2845 0"/>
    <axis xyz="0 0 1"/>
    <limit effort="32.0" lower="-3.927" upper="0.19198" velocity="3.14"/>
  </joint>
  <link name="link4">
    <collision>
      <geometry>
        <cylinder length="0.10" radius="0.08"/>
      </geometry>
      <origin rpy="0 0 0" xyz="0 0.01 -0.062"/>
    </collision>
  </link>
  <joint name="joint4" type="revolute">
    <parent link="link3"/>
    <child link="link4"/>
    <origin rpy="-1.57079632679489661923 0 0" xyz="0.0775 0.3425 0"/>
    <axis xyz="0 0 1"/>
    <limit effort="32.0" lower="-6.28318530718" upper="6.28318530718" velocity="3.14"/>
  </joint>
  <link name="link5">
    <collision>
      <geometry>
        <cylinder length="0.094" radius="0.04"/>
      </geometry>
      <origin rpy="-1.57079632679489661923 0 0" xyz="0.075 0.035 0 "/>
    </collision>
  </link>
  <joint name="joint5" type="revolute">
    <parent link="link4"/>
    <child link="link5"/>
    <origin rpy="1.57079632679489661923 0 0" xyz="0 0 0"/>
    <axis xyz="0 0 1"/>
    <limit effort="32.0" lower="-1.69297" upper="3.14159265359" velocity="3.14"/>
  </joint>
  <link name="link6">
  </link>
  <joint name="joint6" type="revolute">
    <parent link="link5"/>
    <child link="link6"/>
    <origin rpy="-1.57079632679489661923 0 0" xyz="0.076 0.097 0"/>
    <axis xyz="0 0 1"/>
    <limit effort="20.0" lower="-6.28318530718" upper="6.28318530718" velocity="3.14"/>
  </joint>
  <link name="link_eef"/>
  <joint name="joint_eef" type="fixed">
    <origin rpy="0 0 0" xyz="0 0 0"/>
    <parent link="link6"/>
    <child link="link_eef"/>
  </joint>
</robot>
